Internal Server Error: /login/
Traceback (most recent call last):
  File "C:\Users\Darryl\AppData\Local\Programs\Python\Python39\lib\site-packages\django\core\handlers\exception.py", line 55, in inner
    response = get_response(request)
  File "C:\Users\Darryl\AppData\Local\Programs\Python\Python39\lib\site-packages\django\core\handlers\base.py", line 197, in _get_response
    response = wrapped_callback(request, *callback_args, **callback_kwargs)
  File "C:\Users\Darryl\AppData\Local\Programs\Python\Python39\lib\site-packages\django\views\decorators\csrf.py", line 56, in wrapper_view
    return view_func(*args, **kwargs)
  File "C:\Users\Darryl\AppData\Local\Programs\Python\Python39\lib\site-packages\django\views\generic\base.py", line 104, in view
    return self.dispatch(request, *args, **kwargs)
  File "C:\Users\Darryl\AppData\Local\Programs\Python\Python39\lib\site-packages\rest_framework\views.py", line 517, in dispatch
    self.response = self.finalize_response(request, response, *args, **kwargs)
  File "C:\Users\Darryl\AppData\Local\Programs\Python\Python39\lib\site-packages\rest_framework\views.py", line 429, in finalize_response
    assert isinstance(response, HttpResponseBase), (
AssertionError: Expected a `Response`, `HttpResponse` or `StreamingHttpResponse` to be returned from the view, but received a `<class 'NoneType'>`
"POST /login/ HTTP/1.1" 500 80898
Internal Server Error: /login/
Traceback (most recent call last):
  File "C:\Users\Darryl\AppData\Local\Programs\Python\Python39\lib\site-packages\django\core\handlers\exception.py", line 55, in inner
    response = get_response(request)
  File "C:\Users\Darryl\AppData\Local\Programs\Python\Python39\lib\site-packages\django\core\handlers\base.py", line 197, in _get_response
    response = wrapped_callback(request, *callback_args, **callback_kwargs)
  File "C:\Users\Darryl\AppData\Local\Programs\Python\Python39\lib\site-packages\django\views\decorators\csrf.py", line 56, in wrapper_view
    return view_func(*args, **kwargs)
  File "C:\Users\Darryl\AppData\Local\Programs\Python\Python39\lib\site-packages\django\views\generic\base.py", line 104, in view
    return self.dispatch(request, *args, **kwargs)
  File "C:\Users\Darryl\AppData\Local\Programs\Python\Python39\lib\site-packages\rest_framework\views.py", line 517, in dispatch
    self.response = self.finalize_response(request, response, *args, **kwargs)
  File "C:\Users\Darryl\AppData\Local\Programs\Python\Python39\lib\site-packages\rest_framework\views.py", line 429, in finalize_response
    assert isinstance(response, HttpResponseBase), (
AssertionError: Expected a `Response`, `HttpResponse` or `StreamingHttpResponse` to be returned from the view, but received a `<class 'NoneType'>`
"POST /login/ HTTP/1.1" 500 80898
Internal Server Error: /login/
Traceback (most recent call last):
  File "C:\Users\Darryl\AppData\Local\Programs\Python\Python39\lib\site-packages\django\core\handlers\exception.py", line 55, in inner
    response = get_response(request)
  File "C:\Users\Darryl\AppData\Local\Programs\Python\Python39\lib\site-packages\django\core\handlers\base.py", line 197, in _get_response
    response = wrapped_callback(request, *callback_args, **callback_kwargs)
  File "C:\Users\Darryl\AppData\Local\Programs\Python\Python39\lib\site-packages\django\views\decorators\csrf.py", line 56, in wrapper_view
    return view_func(*args, **kwargs)
  File "C:\Users\Darryl\AppData\Local\Programs\Python\Python39\lib\site-packages\django\views\generic\base.py", line 104, in view
    return self.dispatch(request, *args, **kwargs)
  File "C:\Users\Darryl\AppData\Local\Programs\Python\Python39\lib\site-packages\rest_framework\views.py", line 517, in dispatch
    self.response = self.finalize_response(request, response, *args, **kwargs)
  File "C:\Users\Darryl\AppData\Local\Programs\Python\Python39\lib\site-packages\rest_framework\views.py", line 429, in finalize_response
    assert isinstance(response, HttpResponseBase), (
AssertionError: Expected a `Response`, `HttpResponse` or `StreamingHttpResponse` to be returned from the view, but received a `<class 'NoneType'>`
"POST /login/ HTTP/1.1" 500 80898
Internal Server Error: /login/
Traceback (most recent call last):
  File "C:\Users\Darryl\AppData\Local\Programs\Python\Python39\lib\site-packages\django\core\handlers\exception.py", line 55, in inner
    response = get_response(request)
  File "C:\Users\Darryl\AppData\Local\Programs\Python\Python39\lib\site-packages\django\core\handlers\base.py", line 220, in _get_response
    response = response.render()
  File "C:\Users\Darryl\AppData\Local\Programs\Python\Python39\lib\site-packages\django\template\response.py", line 114, in render
    self.content = self.rendered_content
  File "C:\Users\Darryl\AppData\Local\Programs\Python\Python39\lib\site-packages\rest_framework\response.py", line 74, in rendered_content
    ret = renderer.render(self.data, accepted_media_type, context)
  File "C:\Users\Darryl\AppData\Local\Programs\Python\Python39\lib\site-packages\rest_framework\renderers.py", line 100, in render
    ret = json.dumps(
  File "C:\Users\Darryl\AppData\Local\Programs\Python\Python39\lib\site-packages\rest_framework\utils\json.py", line 25, in dumps
    return json.dumps(*args, **kwargs)
  File "C:\Users\Darryl\AppData\Local\Programs\Python\Python39\lib\json\__init__.py", line 234, in dumps
    return cls(
  File "C:\Users\Darryl\AppData\Local\Programs\Python\Python39\lib\json\encoder.py", line 199, in encode
    chunks = self.iterencode(o, _one_shot=True)
  File "C:\Users\Darryl\AppData\Local\Programs\Python\Python39\lib\json\encoder.py", line 257, in iterencode
    return _iterencode(o, 0)
  File "C:\Users\Darryl\AppData\Local\Programs\Python\Python39\lib\site-packages\rest_framework\utils\encoders.py", line 67, in default
    return super().default(obj)
  File "C:\Users\Darryl\AppData\Local\Programs\Python\Python39\lib\json\encoder.py", line 179, in default
    raise TypeError(f'Object of type {o.__class__.__name__} '
TypeError: Object of type User is not JSON serializable
"POST /login/ HTTP/1.1" 500 102929
Internal Server Error: /login/
Traceback (most recent call last):
  File "C:\Users\Darryl\AppData\Local\Programs\Python\Python39\lib\site-packages\django\core\handlers\exception.py", line 55, in inner
    response = get_response(request)
  File "C:\Users\Darryl\AppData\Local\Programs\Python\Python39\lib\site-packages\django\core\handlers\base.py", line 220, in _get_response
    response = response.render()
  File "C:\Users\Darryl\AppData\Local\Programs\Python\Python39\lib\site-packages\django\template\response.py", line 114, in render
    self.content = self.rendered_content
  File "C:\Users\Darryl\AppData\Local\Programs\Python\Python39\lib\site-packages\rest_framework\response.py", line 74, in rendered_content
    ret = renderer.render(self.data, accepted_media_type, context)
  File "C:\Users\Darryl\AppData\Local\Programs\Python\Python39\lib\site-packages\rest_framework\renderers.py", line 100, in render
    ret = json.dumps(
  File "C:\Users\Darryl\AppData\Local\Programs\Python\Python39\lib\site-packages\rest_framework\utils\json.py", line 25, in dumps
    return json.dumps(*args, **kwargs)
  File "C:\Users\Darryl\AppData\Local\Programs\Python\Python39\lib\json\__init__.py", line 234, in dumps
    return cls(
  File "C:\Users\Darryl\AppData\Local\Programs\Python\Python39\lib\json\encoder.py", line 199, in encode
    chunks = self.iterencode(o, _one_shot=True)
  File "C:\Users\Darryl\AppData\Local\Programs\Python\Python39\lib\json\encoder.py", line 257, in iterencode
    return _iterencode(o, 0)
  File "C:\Users\Darryl\AppData\Local\Programs\Python\Python39\lib\site-packages\rest_framework\utils\encoders.py", line 67, in default
    return super().default(obj)
  File "C:\Users\Darryl\AppData\Local\Programs\Python\Python39\lib\json\encoder.py", line 179, in default
    raise TypeError(f'Object of type {o.__class__.__name__} '
TypeError: Object of type User is not JSON serializable
"POST /login/ HTTP/1.1" 500 104542
Internal Server Error: /login/
Traceback (most recent call last):
  File "C:\Users\Darryl\AppData\Local\Programs\Python\Python39\lib\site-packages\django\core\handlers\exception.py", line 55, in inner
    response = get_response(request)
  File "C:\Users\Darryl\AppData\Local\Programs\Python\Python39\lib\site-packages\django\core\handlers\base.py", line 220, in _get_response
    response = response.render()
  File "C:\Users\Darryl\AppData\Local\Programs\Python\Python39\lib\site-packages\django\template\response.py", line 114, in render
    self.content = self.rendered_content
  File "C:\Users\Darryl\AppData\Local\Programs\Python\Python39\lib\site-packages\rest_framework\response.py", line 74, in rendered_content
    ret = renderer.render(self.data, accepted_media_type, context)
  File "C:\Users\Darryl\AppData\Local\Programs\Python\Python39\lib\site-packages\rest_framework\renderers.py", line 100, in render
    ret = json.dumps(
  File "C:\Users\Darryl\AppData\Local\Programs\Python\Python39\lib\site-packages\rest_framework\utils\json.py", line 25, in dumps
    return json.dumps(*args, **kwargs)
  File "C:\Users\Darryl\AppData\Local\Programs\Python\Python39\lib\json\__init__.py", line 234, in dumps
    return cls(
  File "C:\Users\Darryl\AppData\Local\Programs\Python\Python39\lib\json\encoder.py", line 199, in encode
    chunks = self.iterencode(o, _one_shot=True)
  File "C:\Users\Darryl\AppData\Local\Programs\Python\Python39\lib\json\encoder.py", line 257, in iterencode
    return _iterencode(o, 0)
  File "C:\Users\Darryl\AppData\Local\Programs\Python\Python39\lib\site-packages\rest_framework\utils\encoders.py", line 67, in default
    return super().default(obj)
  File "C:\Users\Darryl\AppData\Local\Programs\Python\Python39\lib\json\encoder.py", line 179, in default
    raise TypeError(f'Object of type {o.__class__.__name__} '
TypeError: Object of type User is not JSON serializable
"POST /login/ HTTP/1.1" 500 104542
Internal Server Error: /refresh/
Traceback (most recent call last):
  File "C:\Users\Darryl\AppData\Local\Programs\Python\Python39\lib\site-packages\django\core\handlers\exception.py", line 55, in inner
    response = get_response(request)
  File "C:\Users\Darryl\AppData\Local\Programs\Python\Python39\lib\site-packages\django\core\handlers\base.py", line 197, in _get_response
    response = wrapped_callback(request, *callback_args, **callback_kwargs)
  File "C:\Users\Darryl\AppData\Local\Programs\Python\Python39\lib\site-packages\django\views\decorators\csrf.py", line 56, in wrapper_view
    return view_func(*args, **kwargs)
  File "C:\Users\Darryl\AppData\Local\Programs\Python\Python39\lib\site-packages\django\views\generic\base.py", line 104, in view
    return self.dispatch(request, *args, **kwargs)
  File "C:\Users\Darryl\AppData\Local\Programs\Python\Python39\lib\site-packages\rest_framework\views.py", line 515, in dispatch
    response = self.handle_exception(exc)
  File "C:\Users\Darryl\AppData\Local\Programs\Python\Python39\lib\site-packages\rest_framework\views.py", line 475, in handle_exception
    self.raise_uncaught_exception(exc)
  File "C:\Users\Darryl\AppData\Local\Programs\Python\Python39\lib\site-packages\rest_framework\views.py", line 486, in raise_uncaught_exception
    raise exc
  File "C:\Users\Darryl\AppData\Local\Programs\Python\Python39\lib\site-packages\rest_framework\views.py", line 512, in dispatch
    response = handler(request, *args, **kwargs)
  File "C:\MyProjects\Django\djproj\users\views.py", line 73, in post
    request.data._mutable = True
AttributeError: 'dict' object has no attribute '_mutable'
Internal Server Error: /refresh/
Traceback (most recent call last):
  File "C:\Users\Darryl\AppData\Local\Programs\Python\Python39\lib\site-packages\django\core\handlers\exception.py", line 55, in inner
    response = get_response(request)
  File "C:\Users\Darryl\AppData\Local\Programs\Python\Python39\lib\site-packages\django\core\handlers\base.py", line 197, in _get_response
    response = wrapped_callback(request, *callback_args, **callback_kwargs)
  File "C:\Users\Darryl\AppData\Local\Programs\Python\Python39\lib\site-packages\django\views\decorators\csrf.py", line 56, in wrapper_view
    return view_func(*args, **kwargs)
  File "C:\Users\Darryl\AppData\Local\Programs\Python\Python39\lib\site-packages\django\views\generic\base.py", line 104, in view
    return self.dispatch(request, *args, **kwargs)
  File "C:\Users\Darryl\AppData\Local\Programs\Python\Python39\lib\site-packages\rest_framework\views.py", line 515, in dispatch
    response = self.handle_exception(exc)
  File "C:\Users\Darryl\AppData\Local\Programs\Python\Python39\lib\site-packages\rest_framework\views.py", line 475, in handle_exception
    self.raise_uncaught_exception(exc)
  File "C:\Users\Darryl\AppData\Local\Programs\Python\Python39\lib\site-packages\rest_framework\views.py", line 486, in raise_uncaught_exception
    raise exc
  File "C:\Users\Darryl\AppData\Local\Programs\Python\Python39\lib\site-packages\rest_framework\views.py", line 512, in dispatch
    response = handler(request, *args, **kwargs)
  File "C:\MyProjects\Django\djproj\users\views.py", line 73, in post
    request.data._mutable = True
AttributeError: 'dict' object has no attribute '_mutable'
"POST /refresh/ HTTP/1.1" 500 94636
"POST /refresh/ HTTP/1.1" 500 94636
Internal Server Error: /refresh/
Traceback (most recent call last):
  File "C:\Users\Darryl\AppData\Local\Programs\Python\Python39\lib\site-packages\django\core\handlers\exception.py", line 55, in inner
    response = get_response(request)
  File "C:\Users\Darryl\AppData\Local\Programs\Python\Python39\lib\site-packages\django\core\handlers\base.py", line 197, in _get_response
    response = wrapped_callback(request, *callback_args, **callback_kwargs)
  File "C:\Users\Darryl\AppData\Local\Programs\Python\Python39\lib\site-packages\django\views\decorators\csrf.py", line 56, in wrapper_view
    return view_func(*args, **kwargs)
  File "C:\Users\Darryl\AppData\Local\Programs\Python\Python39\lib\site-packages\django\views\generic\base.py", line 104, in view
    return self.dispatch(request, *args, **kwargs)
  File "C:\Users\Darryl\AppData\Local\Programs\Python\Python39\lib\site-packages\rest_framework\views.py", line 515, in dispatch
    response = self.handle_exception(exc)
  File "C:\Users\Darryl\AppData\Local\Programs\Python\Python39\lib\site-packages\rest_framework\views.py", line 475, in handle_exception
    self.raise_uncaught_exception(exc)
  File "C:\Users\Darryl\AppData\Local\Programs\Python\Python39\lib\site-packages\rest_framework\views.py", line 486, in raise_uncaught_exception
    raise exc
  File "C:\Users\Darryl\AppData\Local\Programs\Python\Python39\lib\site-packages\rest_framework\views.py", line 512, in dispatch
    response = handler(request, *args, **kwargs)
  File "C:\MyProjects\Django\djproj\users\views.py", line 73, in post
    request.data._mutable = True
AttributeError: 'dict' object has no attribute '_mutable'
Internal Server Error: /refresh/
Traceback (most recent call last):
  File "C:\Users\Darryl\AppData\Local\Programs\Python\Python39\lib\site-packages\django\core\handlers\exception.py", line 55, in inner
    response = get_response(request)
  File "C:\Users\Darryl\AppData\Local\Programs\Python\Python39\lib\site-packages\django\core\handlers\base.py", line 197, in _get_response
    response = wrapped_callback(request, *callback_args, **callback_kwargs)
  File "C:\Users\Darryl\AppData\Local\Programs\Python\Python39\lib\site-packages\django\views\decorators\csrf.py", line 56, in wrapper_view
    return view_func(*args, **kwargs)
  File "C:\Users\Darryl\AppData\Local\Programs\Python\Python39\lib\site-packages\django\views\generic\base.py", line 104, in view
    return self.dispatch(request, *args, **kwargs)
  File "C:\Users\Darryl\AppData\Local\Programs\Python\Python39\lib\site-packages\rest_framework\views.py", line 515, in dispatch
    response = self.handle_exception(exc)
  File "C:\Users\Darryl\AppData\Local\Programs\Python\Python39\lib\site-packages\rest_framework\views.py", line 475, in handle_exception
    self.raise_uncaught_exception(exc)
  File "C:\Users\Darryl\AppData\Local\Programs\Python\Python39\lib\site-packages\rest_framework\views.py", line 486, in raise_uncaught_exception
    raise exc
  File "C:\Users\Darryl\AppData\Local\Programs\Python\Python39\lib\site-packages\rest_framework\views.py", line 512, in dispatch
    response = handler(request, *args, **kwargs)
  File "C:\MyProjects\Django\djproj\users\views.py", line 73, in post
    request.data._mutable = True
AttributeError: 'dict' object has no attribute '_mutable'
"POST /refresh/ HTTP/1.1" 500 94636
"POST /refresh/ HTTP/1.1" 500 94636
Internal Server Error: /refresh/
Traceback (most recent call last):
  File "C:\Users\Darryl\AppData\Local\Programs\Python\Python39\lib\site-packages\django\core\handlers\exception.py", line 55, in inner
    response = get_response(request)
  File "C:\Users\Darryl\AppData\Local\Programs\Python\Python39\lib\site-packages\django\core\handlers\base.py", line 197, in _get_response
    response = wrapped_callback(request, *callback_args, **callback_kwargs)
  File "C:\Users\Darryl\AppData\Local\Programs\Python\Python39\lib\site-packages\django\views\decorators\csrf.py", line 56, in wrapper_view
    return view_func(*args, **kwargs)
  File "C:\Users\Darryl\AppData\Local\Programs\Python\Python39\lib\site-packages\django\views\generic\base.py", line 104, in view
    return self.dispatch(request, *args, **kwargs)
  File "C:\Users\Darryl\AppData\Local\Programs\Python\Python39\lib\site-packages\rest_framework\views.py", line 515, in dispatch
    response = self.handle_exception(exc)
  File "C:\Users\Darryl\AppData\Local\Programs\Python\Python39\lib\site-packages\rest_framework\views.py", line 475, in handle_exception
    self.raise_uncaught_exception(exc)
  File "C:\Users\Darryl\AppData\Local\Programs\Python\Python39\lib\site-packages\rest_framework\views.py", line 486, in raise_uncaught_exception
    raise exc
  File "C:\Users\Darryl\AppData\Local\Programs\Python\Python39\lib\site-packages\rest_framework\views.py", line 512, in dispatch
    response = handler(request, *args, **kwargs)
  File "C:\MyProjects\Django\djproj\users\views.py", line 73, in post
    request.data._mutable = True
AttributeError: 'dict' object has no attribute '_mutable'
Internal Server Error: /refresh/
Traceback (most recent call last):
  File "C:\Users\Darryl\AppData\Local\Programs\Python\Python39\lib\site-packages\django\core\handlers\exception.py", line 55, in inner
    response = get_response(request)
  File "C:\Users\Darryl\AppData\Local\Programs\Python\Python39\lib\site-packages\django\core\handlers\base.py", line 197, in _get_response
    response = wrapped_callback(request, *callback_args, **callback_kwargs)
  File "C:\Users\Darryl\AppData\Local\Programs\Python\Python39\lib\site-packages\django\views\decorators\csrf.py", line 56, in wrapper_view
    return view_func(*args, **kwargs)
  File "C:\Users\Darryl\AppData\Local\Programs\Python\Python39\lib\site-packages\django\views\generic\base.py", line 104, in view
    return self.dispatch(request, *args, **kwargs)
  File "C:\Users\Darryl\AppData\Local\Programs\Python\Python39\lib\site-packages\rest_framework\views.py", line 515, in dispatch
    response = self.handle_exception(exc)
  File "C:\Users\Darryl\AppData\Local\Programs\Python\Python39\lib\site-packages\rest_framework\views.py", line 475, in handle_exception
    self.raise_uncaught_exception(exc)
  File "C:\Users\Darryl\AppData\Local\Programs\Python\Python39\lib\site-packages\rest_framework\views.py", line 486, in raise_uncaught_exception
    raise exc
  File "C:\Users\Darryl\AppData\Local\Programs\Python\Python39\lib\site-packages\rest_framework\views.py", line 512, in dispatch
    response = handler(request, *args, **kwargs)
  File "C:\MyProjects\Django\djproj\users\views.py", line 73, in post
    request.data._mutable = True
AttributeError: 'dict' object has no attribute '_mutable'
"POST /refresh/ HTTP/1.1" 500 94636
"POST /refresh/ HTTP/1.1" 500 94636
Internal Server Error: /refresh/
Traceback (most recent call last):
  File "C:\Users\Darryl\AppData\Local\Programs\Python\Python39\lib\site-packages\django\core\handlers\exception.py", line 55, in inner
    response = get_response(request)
  File "C:\Users\Darryl\AppData\Local\Programs\Python\Python39\lib\site-packages\django\core\handlers\base.py", line 197, in _get_response
    response = wrapped_callback(request, *callback_args, **callback_kwargs)
  File "C:\Users\Darryl\AppData\Local\Programs\Python\Python39\lib\site-packages\django\views\decorators\csrf.py", line 56, in wrapper_view
    return view_func(*args, **kwargs)
  File "C:\Users\Darryl\AppData\Local\Programs\Python\Python39\lib\site-packages\django\views\generic\base.py", line 104, in view
    return self.dispatch(request, *args, **kwargs)
  File "C:\Users\Darryl\AppData\Local\Programs\Python\Python39\lib\site-packages\rest_framework\views.py", line 515, in dispatch
    response = self.handle_exception(exc)
  File "C:\Users\Darryl\AppData\Local\Programs\Python\Python39\lib\site-packages\rest_framework\views.py", line 475, in handle_exception
    self.raise_uncaught_exception(exc)
  File "C:\Users\Darryl\AppData\Local\Programs\Python\Python39\lib\site-packages\rest_framework\views.py", line 486, in raise_uncaught_exception
    raise exc
  File "C:\Users\Darryl\AppData\Local\Programs\Python\Python39\lib\site-packages\rest_framework\views.py", line 512, in dispatch
    response = handler(request, *args, **kwargs)
  File "C:\MyProjects\Django\djproj\users\views.py", line 75, in post
    request.data._mutable = True
AttributeError: 'dict' object has no attribute '_mutable'
Internal Server Error: /refresh/
Traceback (most recent call last):
  File "C:\Users\Darryl\AppData\Local\Programs\Python\Python39\lib\site-packages\django\core\handlers\exception.py", line 55, in inner
    response = get_response(request)
  File "C:\Users\Darryl\AppData\Local\Programs\Python\Python39\lib\site-packages\django\core\handlers\base.py", line 197, in _get_response
    response = wrapped_callback(request, *callback_args, **callback_kwargs)
  File "C:\Users\Darryl\AppData\Local\Programs\Python\Python39\lib\site-packages\django\views\decorators\csrf.py", line 56, in wrapper_view
    return view_func(*args, **kwargs)
  File "C:\Users\Darryl\AppData\Local\Programs\Python\Python39\lib\site-packages\django\views\generic\base.py", line 104, in view
    return self.dispatch(request, *args, **kwargs)
  File "C:\Users\Darryl\AppData\Local\Programs\Python\Python39\lib\site-packages\rest_framework\views.py", line 515, in dispatch
    response = self.handle_exception(exc)
  File "C:\Users\Darryl\AppData\Local\Programs\Python\Python39\lib\site-packages\rest_framework\views.py", line 475, in handle_exception
    self.raise_uncaught_exception(exc)
  File "C:\Users\Darryl\AppData\Local\Programs\Python\Python39\lib\site-packages\rest_framework\views.py", line 486, in raise_uncaught_exception
    raise exc
  File "C:\Users\Darryl\AppData\Local\Programs\Python\Python39\lib\site-packages\rest_framework\views.py", line 512, in dispatch
    response = handler(request, *args, **kwargs)
  File "C:\MyProjects\Django\djproj\users\views.py", line 75, in post
    request.data._mutable = True
AttributeError: 'dict' object has no attribute '_mutable'
"POST /refresh/ HTTP/1.1" 500 94636
"POST /refresh/ HTTP/1.1" 500 94636
